Workbook
Name Slicer_Month_Proper: #N/A
Name Slicer_Type__Income_Expense: #N/A

Sheet Data
A1: Date | B1: Details | C1: Debit | D1: Credit | E1: Balance | F1: Month | G1: Type (Income/Expense) | H1: Category | I1: Amount | J1: Month(Proper) | K1: Amount(Positive)
A2: 45748 | B2: EMPLOYER DEP Sa lary of Mar | D2: 114008 | E2: 115118.18 | F2: =TEXT(Account_Data[[#This Row],[Date]],"mmm-yyyy") -> Apr-2025 | G2: =IF(Account_Data[[#This Row],[Credit]]>0,"Income","Expense") -> Income | H2: =IF(AND(Account_Data[[#This Row],[Credit]]>0,ISNUMBER(SEARCH("TFR",Account_Data[[#This Row],[Details]])),Account_Data[[#This Row],[Credit]]>=200000),"Loan Taken", IF(AND(Account_Data[[#This Row],[Debit]]>0,OR(ISNUMBER(SEARCH("ETMONEY",Account_Data[[#This Row],[Details]])),ISNUMBER(SEARCH("PGIM",Account_Data[[#This Row],[Details]])),ISNUMBER(SEARCH("CANARA",Account_Data[[#This Row],[Details]])))),"Investment (Outflow)", IF(AND(Account_Data[[#This Row],[Credit]]>0,OR(ISNUMBER(SEARCH("PGIM",Account_Data[[#This Row],[Details]])),ISNUMBER(SEARCH("CANARA",Account_Data[[#This Row],[Details]])),ISNUMBER(SEARCH("MUTUAL",Account_Data[[#This Row],[Details]])))),"Investment Return", IF(OR(ISNUMBER(SEARCH("LOAN",Account_Data[[#This Row],[Details]])),ISNUMBER(SEARCH("RECOVERY",Account_Data[[#This Row],[Details]]))),"Loan Payment", IF(OR(ISNUMBER(SEARCH("SALARY",Account_Data[[#This Row],[Details]])),ISNUMBER(SEARCH("EMPLOYER DEP",Account_Data[[#This Row],[Details]]))),"Income", IF(OR(ISNUMBER(SEARCH("ACH",Account_Data[[#This Row],[Details]])),ISNUMBER(SEARCH("DIRECT DR",Account_Data[[#This Row],[Details]]))),"EMI", IF(ISNUMBER(SEARCH("ATM",Account_Data[[#This Row],[Details]])),"Cash", IF(ISNUMBER(SEARCH("UPI",Account_Data[[#This Row],[Details]])),"UPI Expense",IF(ISNUMBER(SEARCH("W TFR",Account_Data[[#This Row],[Details]])),"Transfer","Other"))))))))) -> Income | I2: =Account_Data[[#This Row],[Credit]]-Account_Data[[#This Row],[Debit]] -> 114008 | J2: =EOMONTH(Account_Data[[#This Row],[Date]],0) -> 45777 | K2: =ABS(Account_Data[[#This Row],[Amount]]) -> 114008
A3: 45749 | B3: DEBIT ACHDr YESB TP ACH INDIANE | C3: 2000 | E3: 113118.18 | F3: =TEXT(Account_Data[[#This Row],[Date]],"mmm-yyyy") -> Apr-2025 | G3: =IF(Account_Data[[#This Row],[Credit]]>0,"Income","Expense") -> Expense | H3: =IF(AND(Account_Data[[#This Row],[Credit]]>0,ISNUMBER(SEARCH("TFR",Account_Data[[#This Row],[Details]])),Account_Data[[#This Row],[Credit]]>=200000),"Loan Taken", IF(AND(Account_Data[[#This Row],[Debit]]>0,OR(ISNUMBER(SEARCH("ETMONEY",Account_Data[[#This Row],[Details]])),ISNUMBER(SEARCH("PGIM",Account_Data[[#This Row],[Details]])),ISNUMBER(SEARCH("CANARA",Account_Data[[#This Row],[Details]])))),"Investment (Outflow)", IF(AND(Account_Data[[#This Row],[Credit]]>0,OR(ISNUMBER(SEARCH("PGIM",Account_Data[[#This Row],[Details]])),ISNUMBER(SEARCH("CANARA",Account_Data[[#This Row],[Details]])),ISNUMBER(SEARCH("MUTUAL",Account_Data[[#This Row],[Details]])))),"Investment Return", IF(OR(ISNUMBER(SEARCH("LOAN",Account_Data[[#This Row],[Details]])),ISNUMBER(SEARCH("RECOVERY",Account_Data[[#This Row],[Details]]))),"Loan Payment", IF(OR(ISNUMBER(SEARCH("SALARY",Account_Data[[#This Row],[Details]])),ISNUMBER(SEARCH("EMPLOYER DEP",Account_Data[[#This Row],[Details]]))),"Income", IF(OR(ISNUMBER(SEARCH("ACH",Account_Data[[#This Row],[Details]])),ISNUMBER(SEARCH("DIRECT DR",Account_Data[[#This Row],[Details]]))),"EMI", IF(ISNUMBER(SEARCH("ATM",Account_Data[[#This Row],[Details]])),"Cash", IF(ISNUMBER(SEARCH("UPI",Account_Data[[#This Row],[Details]])),"UPI Expense",IF(ISNUMBER(SEARCH("W TFR",Account_Data[[#This Row],[Details]])),"Transfer","Other"))))))))) -> EMI | I3: =Account_Data[[#This Row],[Credit]]-Account_Data[[#This Row],[Debit]] -> -2000 | J3: =EOMONTH(Account_Data[[#This Row],[Date]],0) -> 45777 | K3: =ABS(Account_Data[[#This Row],[Amount]]) -> 2000
A4: 45749 | B4: DEBIT ACHDr YESB TP ACH INDIANE | C4: 2000 | E4: 111118.18 | F4: =TEXT(Account_Data[[#This Row],[Date]],"mmm-yyyy") -> Apr-2025 | G4: =IF(Account_Data[[#This Row],[Credit]]>0,"Income","Expense") -> Expense | H4: =IF(AND(Account_Data[[#This Row],[Credit]]>0,ISNUMBER(SEARCH("TFR",Account_Data[[#This Row],[Details]])),Account_Data[[#This Row],[Credit]]>=200000),"Loan Taken", IF(AND(Account_Data[[#This Row],[Debit]]>0,OR(ISNUMBER(SEARCH("ETMONEY",Account_Data[[#This Row],[Details]])),ISNUMBER(SEARCH("PGIM",Account_Data[[#This Row],[Details]])),ISNUMBER(SEARCH("CANARA",Account_Data[[#This Row],[Details]])))),"Investment (Outflow)", IF(AND(Account_Data[[#This Row],[Credit]]>0,OR(ISNUMBER(SEARCH("PGIM",Account_Data[[#This Row],[Details]])),ISNUMBER(SEARCH("CANARA",Account_Data[[#This Row],[Details]])),ISNUMBER(SEARCH("MUTUAL",Account_Data[[#This Row],[Details]])))),"Investment Return", IF(OR(ISNUMBER(SEARCH("LOAN",Account_Data[[#This Row],[Details]])),ISNUMBER(SEARCH("RECOVERY",Account_Data[[#This Row],[Details]]))),"Loan Payment", IF(OR(ISNUMBER(SEARCH("SALARY",Account_Data[[#This Row],[Details]])),ISNUMBER(SEARCH("EMPLOYER DEP",Account_Data[[#This Row],[Details]]))),"Income", IF(OR(ISNUMBER(SEARCH("ACH",Account_Data[[#This Row],[Details]])),ISNUMBER(SEARCH("DIRECT DR",Account_Data[[#This Row],[Details]]))),"EMI", IF(ISNUMBER(SEARCH("ATM",Account_Data[[#This Row],[Details]])),"Cash", IF(ISNUMBER(SEARCH("UPI",Account_Data[[#This Row],[Details]])),"UPI Expense",IF(ISNUMBER(SEARCH("W TFR",Account_Data[[#This Row],[Details]])),"Transfer","Other"))))))))) -> EMI | I4: =Account_Data[[#This Row],[Credit]]-Account_Data[[#This Row],[Debit]] -> -2000 | J4: =EOMONTH(Account_Data[[#This Row],[Date]],0) -> 45777 | K4: =ABS(Account_Data[[#This Row],[Amount]]) -> 2000
A5: 45749 | B5: DEBIT ACHDr YESB TP ACH INDIANE | C5: 3000 | E5: 108118.18 | F5: =TEXT(Account_Data[[#This Row],[Date]],"mmm-yyyy") -> Apr-2025 | G5: =IF(Account_Data[[#This Row],[Credit]]>0,"Income","Expense") -> Expense | H5: =IF(AND(Account_Data[[#This Row],[Credit]]>0,ISNUMBER(SEARCH("TFR",Account_Data[[#This Row],[Details]])),Account_Data[[#This Row],[Credit]]>=200000),"Loan Taken", IF(AND(Account_Data[[#This Row],[Debit]]>0,OR(ISNUMBER(SEARCH("ETMONEY",Account_Data[[#This Row],[Details]])),ISNUMBER(SEARCH("PGIM",Account_Data[[#This Row],[Details]])),ISNUMBER(SEARCH("CANARA",Account_Data[[#This Row],[Details]])))),"Investment (Outflow)", IF(AND(Account_Data[[#This Row],[Credit]]>0,OR(ISNUMBER(SEARCH("PGIM",Account_Data[[#This Row],[Details]])),ISNUMBER(SEARCH("CANARA",Account_Data[[#This Row],[Details]])),ISNUMBER(SEARCH("MUTUAL",Account_Data[[#This Row],[Details]])))),"Investment Return", IF(OR(ISNUMBER(SEARCH("LOAN",Account_Data[[#This Row],[Details]])),ISNUMBER(SEARCH("RECOVERY",Account_Data[[#This Row],[Details]]))),"Loan Payment", IF(OR(ISNUMBER(SEARCH("SALARY",Account_Data[[#This Row],[Details]])),ISNUMBER(SEARCH("EMPLOYER DEP",Account_Data[[#This Row],[Details]]))),"Income", IF(OR(ISNUMBER(SEARCH("ACH",Account_Data[[#This Row],[Details]])),ISNUMBER(SEARCH("DIRECT DR",Account_Data[[#This Row],[Details]]))),"EMI", IF(ISNUMBER(SEARCH("ATM",Account_Data[[#This Row],[Details]])),"Cash", IF(ISNUMBER(SEARCH("UPI",Account_Data[[#This Row],[Details]])),"UPI Expense",IF(ISNUMBER(SEARCH("W TFR",Account_Data[[#This Row],[Details]])),"Transfer","Other"))))))))) -> EMI | I5: =Account_Data[[#This Row],[Credit]]-Account_Data[[#This Row],[Debit]] -> -3000 | J5: =EOMONTH(Account_Data[[#This Row],[Date]],0) -> 45777 | K5: =ABS(Account_Data[[#This Row],[Amount]]) -> 3000
A6: 45749 | B6: DEBIT ACHDr YESB TP ACH INDIANE | C6: 2000 | E6: 106118.18 | F6: =TEXT(Account_Data[[#This Row],[Date]],"mmm-yyyy") -> Apr-2025 | G6: =IF(Account_Data[[#This Row],[Credit]]>0,"Income","Expense") -> Expense | H6: =IF(AND(Account_Data[[#This Row],[Credit]]>0,ISNUMBER(SEARCH("TFR",Account_Data[[#This Row],[Details]])),Account_Data[[#This Row],[Credit]]>=200000),"Loan Taken", IF(AND(Account_Data[[#This Row],[Debit]]>0,OR(ISNUMBER(SEARCH("ETMONEY",Account_Data[[#This Row],[Details]])),ISNUMBER(SEARCH("PGIM",Account_Data[[#This Row],[Details]])),ISNUMBER(SEARCH("CANARA",Account_Data[[#This Row],[Details]])))),"Investment (Outflow)", IF(AND(Account_Data[[#This Row],[Credit]]>0,OR(ISNUMBER(SEARCH("PGIM",Account_Data[[#This Row],[Details]])),ISNUMBER(SEARCH("CANARA",Account_Data[[#This Row],[Details]])),ISNUMBER(SEARCH("MUTUAL",Account_Data[[#This Row],[Details]])))),"Investment Return", IF(OR(ISNUMBER(SEARCH("LOAN",Account_Data[[#This Row],[Details]])),ISNUMBER(SEARCH("RECOVERY",Account_Data[[#This Row],[Details]]))),"Loan Payment", IF(OR(ISNUMBER(SEARCH("SALARY",Account_Data[[#This Row],[Details]])),ISNUMBER(SEARCH("EMPLOYER DEP",Account_Data[[#This Row],[Details]]))),"Income", IF(OR(ISNUMBER(SEARCH("ACH",Account_Data[[#This Row],[Details]])),ISNUMBER(SEARCH("DIRECT DR",Account_Data[[#This Row],[Details]]))),"EMI", IF(ISNUMBER(SEARCH("ATM",Account_Data[[#This Row],[Details]])),"Cash", IF(ISNUMBER(SEARCH("UPI",Account_Data[[#This Row],[Details]])),"UPI Expense",IF(ISNUMBER(SEARCH("W TFR",Account_Data[[#This Row],[Details]])),"Transfer","Other"))))))))) -> EMI | I6: =Account_Data[[#This Row],[Credit]]-Account_Data[[#This Row],[Debit]] -> -2000 | J6: =EOMONTH(Account_Data[[#This Row],[Date]],0) -> 45777 | K6: =ABS(Account_Data[[#This Row],[Amount]]) -> 2000
A7: 45749 | B7: DEBIT ACHDr YESB TP ACH INDIANE | C7: 5000 | E7: 101118.18 | F7: =TEXT(Account_Data[[#This Row],[Date]],"mmm-yyyy") -> Apr-2025 | G7: =IF(Account_Data[[#This Row],[Credit]]>0,"Income","Expense") -> Expense | H7: =IF(AND(Account_Data[[#This Row],[Credit]]>0,ISNUMBER(SEARCH("TFR",Account_Data[[#This Row],[Details]])),Account_Data[[#This Row],[Credit]]>=200000),"Loan Taken", IF(AND(Account_Data[[#This Row],[Debit]]>0,OR(ISNUMBER(SEARCH("ETMONEY",Account_Data[[#This Row],[Details]])),ISNUMBER(SEARCH("PGIM",Account_Data[[#This Row],[Details]])),ISNUMBER(SEARCH("CANARA",Account_Data[[#This Row],[Details]])))),"Investment (Outflow)", IF(AND(Account_Data[[#This Row],[Credit]]>0,OR(ISNUMBER(SEARCH("PGIM",Account_Data[[#This Row],[Details]])),ISNUMBER(SEARCH("CANARA",Account_Data[[#This Row],[Details]])),ISNUMBER(SEARCH("MUTUAL",Account_Data[[#This Row],[Details]])))),"Investment Return", IF(OR(ISNUMBER(SEARCH("LOAN",Account_Data[[#This Row],[Details]])),ISNUMBER(SEARCH("RECOVERY",Account_Data[[#This Row],[Details]]))),"Loan Payment", IF(OR(ISNUMBER(SEARCH("SALARY",Account_Data[[#This Row],[Details]])),ISNUMBER(SEARCH("EMPLOYER DEP",Account_Data[[#This Row],[Details]]))),"Income", IF(OR(ISNUMBER(SEARCH("ACH",Account_Data[[#This Row],[Details]])),ISNUMBER(SEARCH("DIRECT DR",Account_Data[[#This Row],[Details]]))),"EMI", IF(ISNUMBER(SEARCH("ATM",Account_Data[[#This Row],[Details]])),"Cash", IF(ISNUMBER(SEARCH("UPI",Account_Data[[#This Row],[Details]])),"UPI Expense",IF(ISNUMBER(SEARCH("W TFR",Account_Data[[#This Row],[Details]])),"Transfer","Other"))))))))) -> EMI | I7: =Account_Data[[#This Row],[Credit]]-Account_Data[[#This Row],[Debit]] -> -5000 | J7: =EOMONTH(Account_Data[[#This Row],[Date]],0) -> 45777 | K7: =ABS(Account_Data[[#This Row],[Amount]]) -> 5000
A8: 45749 | B8: DEBIT ACHDr YESB TP ACH INDIANE | C8: 5000 | E8: 96118.18 | F8: =TEXT(Account_Data[[#This Row],[Date]],"mmm-yyyy") -> Apr-2025 | G8: =IF(Account_Data[[#This Row],[Credit]]>0,"Income","Expense") -> Expense | H8: =IF(AND(Account_Data[[#This Row],[Credit]]>0,ISNUMBER(SEARCH("TFR",Account_Data[[#This Row],[Details]])),Account_Data[[#This Row],[Credit]]>=200000),"Loan Taken", IF(AND(Account_Data[[#This Row],[Debit]]>0,OR(ISNUMBER(SEARCH("ETMONEY",Account_Data[[#This Row],[Details]])),ISNUMBER(SEARCH("PGIM",Account_Data[[#This Row],[Details]])),ISNUMBER(SEARCH("CANARA",Account_Data[[#This Row],[Details]])))),"Investment (Outflow)", IF(AND(Account_Data[[#This Row],[Credit]]>0,OR(ISNUMBER(SEARCH("PGIM",Account_Data[[#This Row],[Details]])),ISNUMBER(SEARCH("CANARA",Account_Data[[#This Row],[Details]])),ISNUMBER(SEARCH("MUTUAL",Account_Data[[#This Row],[Details]])))),"Investment Return", IF(OR(ISNUMBER(SEARCH("LOAN",Account_Data[[#This Row],[Details]])),ISNUMBER(SEARCH("RECOVERY",Account_Data[[#This Row],[Details]]))),"Loan Payment", IF(OR(ISNUMBER(SEARCH("SALARY",Account_Data[[#This Row],[Details]])),ISNUMBER(SEARCH("EMPLOYER DEP",Account_Data[[#This Row],[Details]]))),"Income", IF(OR(ISNUMBER(SEARCH("ACH",Account_Data[[#This Row],[Details]])),ISNUMBER(SEARCH("DIRECT DR",Account_Data[[#This Row],[Details]]))),"EMI", IF(ISNUMBER(SEARCH("ATM",Account_Data[[#This Row],[Details]])),"Cash", IF(ISNUMBER(SEARCH("UPI",Account_Data[[#This Row],[Details]])),"UPI Expense",IF(ISNUMBER(SEARCH("W TFR",Account_Data[[#This Row],[Details]])),"Transfer","Other"))))))))) -> EMI | I8: =Account_Data[[#This Row],[Credit]]-Account_Data[[#This Row],[Debit]] -> -5000 | J8: =EOMONTH(Account_Data[[#This Row],[Date]],0) -> 45777 | K8: =ABS(Account_Data[[#This Row],[Amount]]) -> 5000
A9: 45749 | B9: DEBIT ACHDr NACH ETMONEY | C9: 1500 | E9: 94618.18 | F9: =TEXT(Account_Data[[#This Row],[Date]],"mmm-yyyy") -> Apr-2025 | G9: =IF(Account_Data[[#This Row],[Credit]]>0,"Income","Expense") -> Expense | H9: =IF(AND(Account_Data[[#This Row],[Credit]]>0,ISNUMBER(SEARCH("TFR",Account_Data[[#This Row],[Details]])),Account_Data[[#This Row],[Credit]]>=200000),"Loan Taken", IF(AND(Account_Data[[#This Row],[Debit]]>0,OR(ISNUMBER(SEARCH("ETMONEY",Account_Data[[#This Row],[Details]])),ISNUMBER(SEARCH("PGIM",Account_Data[[#This Row],[Details]])),ISNUMBER(SEARCH("CANARA",Account_Data[[#This Row],[Details]])))),"Investment (Outflow)", IF(AND(Account_Data[[#This Row],[Credit]]>0,OR(ISNUMBER(SEARCH("PGIM",Account_Data[[#This Row],[Details]])),ISNUMBER(SEARCH("CANARA",Account_Data[[#This Row],[Details]])),ISNUMBER(SEARCH("MUTUAL",Account_Data[[#This Row],[Details]])))),"Investment Return", IF(OR(ISNUMBER(SEARCH("LOAN",Account_Data[[#This Row],[Details]])),ISNUMBER(SEARCH("RECOVERY",Account_Data[[#This Row],[Details]]))),"Loan Payment", IF(OR(ISNUMBER(SEARCH("SALARY",Account_Data[[#This Row],[Details]])),ISNUMBER(SEARCH("EMPLOYER DEP",Account_Data[[#This Row],[Details]]))),"Income", IF(OR(ISNUMBER(SEARCH("ACH",Account_Data[[#This Row],[Details]])),ISNUMBER(SEARCH("DIRECT DR",Account_Data[[#This Row],[Details]]))),"EMI", IF(ISNUMBER(SEARCH("ATM",Account_Data[[#This Row],[Details]])),"Cash", IF(ISNUMBER(SEARCH("UPI",Account_Data[[#This Row],[Details]])),"UPI Expense",IF(ISNUMBER(SEARCH("W TFR",Account_Data[[#This Row],[Details]])),"Transfer","Other"))))))))) -> Investment (Outflow) | I9: =Account_Data[[#This Row],[Credit]]-Account_Data[[#This Row],[Debit]] -> -1500 | J9: =EOMONTH(Account_Data[[#This Row],[Date]],0) -> 45777 | K9: =ABS(Account_Data[[#This Row],[Amount]]) -> 1500
A10: 45749 | B10: DEBIT ACHDr NACH ETMONEY | C10: 1000 | E10: 93618.18 | F10: =TEXT(Account_Data[[#This Row],[Date]],"mmm-yyyy") -> Apr-2025 | G10: =IF(Account_Data[[#This Row],[Credit]]>0,"Income","Expense") -> Expense | H10: =IF(AND(Account_Data[[#This Row],[Credit]]>0,ISNUMBER(SEARCH("TFR",Account_Data[[#This Row],[Details]])),Account_Data[[#This Row],[Credit]]>=200000),"Loan Taken", IF(AND(Account_Data[[#This Row],[Debit]]>0,OR(ISNUMBER(SEARCH("ETMONEY",Account_Data[[#This Row],[Details]])),ISNUMBER(SEARCH("PGIM",Account_Data[[#This Row],[Details]])),ISNUMBER(SEARCH("CANARA",Account_Data[[#This Row],[Details]])))),"Investment (Outflow)", IF(AND(Account_Data[[#This Row],[Credit]]>0,OR(ISNUMBER(SEARCH("PGIM",Account_Data[[#This Row],[Details]])),ISNUMBER(SEARCH("CANARA",Account_Data[[#This Row],[Details]])),ISNUMBER(SEARCH("MUTUAL",Account_Data[[#This Row],[Details]])))),"Investment Return", IF(OR(ISNUMBER(SEARCH("LOAN",Account_Data[[#This Row],[Details]])),ISNUMBER(SEARCH("RECOVERY",Account_Data[[#This Row],[Details]]))),"Loan Payment", IF(OR(ISNUMBER(SEARCH("SALARY",Account_Data[[#This Row],[Details]])),ISNUMBER(SEARCH("EMPLOYER DEP",Account_Data[[#This Row],[Details]]))),"Income", IF(OR(ISNUMBER(SEARCH("ACH",Account_Data[[#This Row],[Details]])),ISNUMBER(SEARCH("DIRECT DR",Account_Data[[#This Row],[Details]]))),"EMI", IF(ISNUMBER(SEARCH("ATM",Account_Data[[#This Row],[Details]])),"Cash", IF(ISNUMBER(SEARCH("UPI",Account_Data[[#This Row],[Details]])),"UPI Expense",IF(ISNUMBER(SEARCH("W TFR",Account_Data[[#This Row],[Details]])),"Transfer","Other"))))))))) -> Investment (Outflow) | I10: =Account_Data[[#This Row],[Credit]]-Account_Data[[#This Row],[Debit]] -> -1000 | J10: =EOMONTH(Account_Data[[#This Row],[Date]],0) -> 45777 | K10: =ABS(Account_Data[[#This Row],[Amount]]) -> 1000
A11: 45751 | B11: DIRECT DR OF Mr. XYZ ABC H AT | C11: 6280 | E11: 87338.18 | F11: =TEXT(Account_Data[[#This Row],[Date]],"mmm-yyyy") -> Apr-2025 | G11: =IF(Account_Data[[#This Row],[Credit]]>0,"Income","Expense") -> Expense | H11: =IF(AND(Account_Data[[#This Row],[Credit]]>0,ISNUMBER(SEARCH("TFR",Account_Data[[#This Row],[Details]])),Account_Data[[#This Row],[Credit]]>=200000),"Loan Taken", IF(AND(Account_Data[[#This Row],[Debit]]>0,OR(ISNUMBER(SEARCH("ETMONEY",Account_Data[[#This Row],[Details]])),ISNUMBER(SEARCH("PGIM",Account_Data[[#This Row],[Details]])),ISNUMBER(SEARCH("CANARA",Account_Data[[#This Row],[Details]])))),"Investment (Outflow)", IF(AND(Account_Data[[#This Row],[Credit]]>0,OR(ISNUMBER(SEARCH("PGIM",Account_Data[[#This Row],[Details]])),ISNUMBER(SEARCH("CANARA",Account_Data[[#This Row],[Details]])),ISNUMBER(SEARCH("MUTUAL",Account_Data[[#This Row],[Details]])))),"Investment Return", IF(OR(ISNUMBER(SEARCH("LOAN",Account_Data[[#This Row],[Details]])),ISNUMBER(SEARCH("RECOVERY",Account_Data[[#This Row],[Details]]))),"Loan Payment", IF(OR(ISNUMBER(SEARCH("SALARY",Account_Data[[#This Row],[Details]])),ISNUMBER(SEARCH("EMPLOYER DEP",Account_Data[[#This Row],[Details]]))),"Income", IF(OR(ISNUMBER(SEARCH("ACH",Account_Data[[#This Row],[Details]])),ISNUMBER(SEARCH("DIRECT DR",Account_Data[[#This Row],[Details]]))),"EMI", IF(ISNUMBER(SEARCH("ATM",Account_Data[[#This Row],[Details]])),"Cash", IF(ISNUMBER(SEARCH("UPI",Account_Data[[#This Row],[Details]])),"UPI Expense",IF(ISNUMBER(SEARCH("W TFR",Account_Data[[#This Row],[Details]])),"Transfer","Other"))))))))) -> EMI | I11: =Account_Data[[#This Row],[Credit]]-Account_Data[[#This Row],[Debit]] -> -6280 | J11: =EOMONTH(Account_Data[[#This Row],[Date]],0) -> 45777 | K11: =ABS(Account_Data[[#This Row],[Amount]]) -> 6280
A12: 45751 | B12: W TFR UPI/DR//SHAMBHAV/KKBK//P aym AT | C12: 25000 | E12: 62338.18 | F12: =TEXT(Account_Data[[#This Row],[Date]],"mmm-yyyy") -> Apr-2025 | G12: =IF(Account_Data[[#This Row],[Credit]]>0,"Income","Expense") -> Expense | H12: =IF(AND(Account_Data[[#This Row],[Credit]]>0,ISNUMBER(SEARCH("TFR",Account_Data[[#This Row],[Details]])),Account_Data[[#This Row],[Credit]]>=200000),"Loan Taken", IF(AND(Account_Data[[#This Row],[Debit]]>0,OR(ISNUMBER(SEARCH("ETMONEY",Account_Data[[#This Row],[Details]])),ISNUMBER(SEARCH("PGIM",Account_Data[[#This Row],[Details]])),ISNUMBER(SEARCH("CANARA",Account_Data[[#This Row],[Details]])))),"Investment (Outflow)", IF(AND(Account_Data[[#This Row],[Credit]]>0,OR(ISNUMBER(SEARCH("PGIM",Account_Data[[#This Row],[Details]])),ISNUMBER(SEARCH("CANARA",Account_Data[[#This Row],[Details]])),ISNUMBER(SEARCH("MUTUAL",Account_Data[[#This Row],[Details]])))),"Investment Return", IF(OR(ISNUMBER(SEARCH("LOAN",Account_Data[[#This Row],[Details]])),ISNUMBER(SEARCH("RECOVERY",Account_Data[[#This Row],[Details]]))),"Loan Payment", IF(OR(ISNUMBER(SEARCH("SALARY",Account_Data[[#This Row],[Details]])),ISNUMBER(SEARCH("EMPLOYER DEP",Account_Data[[#This Row],[Details]]))),"Income", IF(OR(ISNUMBER(SEARCH("ACH",Account_Data[[#This Row],[Details]])),ISNUMBER(SEARCH("DIRECT DR",Account_Data[[#This Row],[Details]]))),"EMI", IF(ISNUMBER(SEARCH("ATM",Account_Data[[#This Row],[Details]])),"Cash", IF(ISNUMBER(SEARCH("UPI",Account_Data[[#This Row],[Details]])),"UPI Expense",IF(ISNUMBER(SEARCH("W TFR",Account_Data[[#This Row],[Details]])),"Transfer","Other"))))))))) -> UPI Expense | I12: =Account_Data[[#This Row],[Credit]]-Account_Data[[#This Row],[Debit]] -> -25000 | J12: =EOMONTH(Account_Data[[#This Row],[Date]],0) -> 45777 | K12: =ABS(Account_Data[[#This Row],[Amount]]) -> 25000
A13: 45752 | B13: W TFR UPI/DR//Ketto On/YESB/paytm-/O idO AT | C13: 50 | E13: 62288.18 | F13: =TEXT(Account_Data[[#This Row],[Date]],"mmm-yyyy") -> Apr-2025 | G13: =IF(Account_Data[[#This Row],[Credit]]>0,"Income","Expense") -> Expense | H13: =IF(AND(Account_Data[[#This Row],[Credit]]>0,ISNUMBER(SEARCH("TFR",Account_Data[[#This Row],[Details]])),Account_Data[[#This Row],[Credit]]>=200000),"Loan Taken", IF(AND(Account_Data[[#This Row],[Debit]]>0,OR(ISNUMBER(SEARCH("ETMONEY",Account_Data[[#This Row],[Details]])),ISNUMBER(SEARCH("PGIM",Account_Data[[#This Row],[Details]])),ISNUMBER(SEARCH("CANARA",Account_Data[[#This Row],[Details]])))),"Investment (Outflow)", IF(AND(Account_Data[[#This Row],[Credit]]>0,OR(ISNUMBER(SEARCH("PGIM",Account_Data[[#This Row],[Details]])),ISNUMBER(SEARCH("CANARA",Account_Data[[#This Row],[Details]])),ISNUMBER(SEARCH("MUTUAL",Account_Data[[#This Row],[Details]])))),"Investment Return", IF(OR(ISNUMBER(SEARCH("LOAN",Account_Data[[#This Row],[Details]])),ISNUMBER(SEARCH("RECOVERY",Account_Data[[#This Row],[Details]]))),"Loan Payment", IF(OR(ISNUMBER(SEARCH("SALARY",Account_Data[[#This Row],[Details]])),ISNUMBER(SEARCH("EMPLOYER DEP",Account_Data[[#This Row],[Details]]))),"Income", IF(OR(ISNUMBER(SEARCH("ACH",Account_Data[[#This Row],[Details]])),ISNUMBER(SEARCH("DIRECT DR",Account_Data[[#This Row],[Details]]))),"EMI", IF(ISNUMBER(SEARCH("ATM",Account_Data[[#This Row],[Details]])),"Cash", IF(ISNUMBER(SEARCH("UPI",Account_Data[[#This Row],[Details]])),"UPI Expense",IF(ISNUMBER(SEARCH("W TFR",Account_Data[[#This Row],[Details]])),"Transfer","Other"))))))))) -> UPI Expense | I13: =Account_Data[[#This Row],[Credit]]-Account_Data[[#This Row],[Debit]] -> -50 | J13: =EOMONTH(Account_Data[[#This Row],[Date]],0) -> 45777 | K13: =ABS(Account_Data[[#This Row],[Amount]]) -> 50
A14: 45752 | B14: DEBIT ACHDr NACH INSTITUTE FEE | C14: 25394.71 | E14: 36893.47 | F14: =TEXT(Account_Data[[#This Row],[Date]],"mmm-yyyy") -> Apr-2025 | G14: =IF(Account_Data[[#This Row],[Credit]]>0,"Income","Expense") -> Expense | H14: =IF(AND(Account_Data[[#This Row],[Credit]]>0,ISNUMBER(SEARCH("TFR",Account_Data[[#This Row],[Details]])),Account_Data[[#This Row],[Credit]]>=200000),"Loan Taken", IF(AND(Account_Data[[#This Row],[Debit]]>0,OR(ISNUMBER(SEARCH("ETMONEY",Account_Data[[#This Row],[Details]])),ISNUMBER(SEARCH("PGIM",Account_Data[[#This Row],[Details]])),ISNUMBER(SEARCH("CANARA",Account_Data[[#This Row],[Details]])))),"Investment (Outflow)", IF(AND(Account_Data[[#This Row],[Credit]]>0,OR(ISNUMBER(SEARCH("PGIM",Account_Data[[#This Row],[Details]])),ISNUMBER(SEARCH("CANARA",Account_Data[[#This Row],[Details]])),ISNUMBER(SEARCH("MUTUAL",Account_Data[[#This Row],[Details]])))),"Investment Return", IF(OR(ISNUMBER(SEARCH("LOAN",Account_Data[[#This Row],[Details]])),ISNUMBER(SEARCH("RECOVERY",Account_Data[[#This Row],[Details]]))),"Loan Payment", IF(OR(ISNUMBER(SEARCH("SALARY",Account_Data[[#This Row],[Details]])),ISNUMBER(SEARCH("EMPLOYER DEP",Account_Data[[#This Row],[Details]]))),"Income", IF(OR(ISNUMBER(SEARCH("ACH",Account_Data[[#This Row],[Details]])),ISNUMBER(SEARCH("DIRECT DR",Account_Data[[#This Row],[Details]]))),"EMI", IF(ISNUMBER(SEARCH("ATM",Account_Data[[#This Row],[Details]])),"Cash", IF(ISNUMBER(SEARCH("UPI",Account_Data[[#This Row],[Details]])),"UPI Expense",IF(ISNUMBER(SEARCH("W TFR",Account_Data[[#This Row],[Details]])),"Transfer","Other"))))))))) -> EMI | I14: =Account_Data[[#This Row],[Credit]]-Account_Data[[#This Row],[Debit]] -> -25394.71 | J14: =EOMONTH(Account_Data[[#This Row],[Date]],0) -> 45777 | K14: =ABS(Account_Data[[#This Row],[Amount]]) -> 25394.71
A15: 45754 | B15: DIRECT DR OF Mr. XYZ ABC H AT | C15: 8704 | E15: 28189.47 | F15: =TEXT(Account_Data[[#This Row],[Date]],"mmm-yyyy") -> Apr-2025 | G15: =IF(Account_Data[[#This Row],[Credit]]>0,"Income","Expense") -> Expense | H15: =IF(AND(Account_Data[[#This Row],[Credit]]>0,ISNUMBER(SEARCH("TFR",Account_Data[[#This Row],[Details]])),Account_Data[[#This Row],[Credit]]>=200000),"Loan Taken", IF(AND(Account_Data[[#This Row],[Debit]]>0,OR(ISNUMBER(SEARCH("ETMONEY",Account_Data[[#This Row],[Details]])),ISNUMBER(SEARCH("PGIM",Account_Data[[#This Row],[Details]])),ISNUMBER(SEARCH("CANARA",Account_Data[[#This Row],[Details]])))),"Investment (Outflow)", IF(AND(Account_Data[[#This Row],[Credit]]>0,OR(ISNUMBER(SEARCH("PGIM",Account_Data[[#This Row],[Details]])),ISNUMBER(SEARCH("CANARA",Account_Data[[#This Row],[Details]])),ISNUMBER(SEARCH("MUTUAL",Account_Data[[#This Row],[Details]])))),"Investment Return", IF(OR(ISNUMBER(SEARCH("LOAN",Account_Data[[#This Row],[Details]])),ISNUMBER(SEARCH("RECOVERY",Account_Data[[#This Row],[Details]]))),"Loan Payment", IF(OR(ISNUMBER(SEARCH("SALARY",Account_Data[[#This Row],[Details]])),ISNUMBER(SEARCH("EMPLOYER DEP",Account_Data[[#This Row],[Details]]))),"Income", IF(OR(ISNUMBER(SEARCH("ACH",Account_Data[[#This Row],[Details]])),ISNUMBER(SEARCH("DIRECT DR",Account_Data[[#This Row],[Details]]))),"EMI", IF(ISNUMBER(SEARCH("ATM",Account_Data[[#This Row],[Details]])),"Cash", IF(ISNUMBER(SEARCH("UPI",Account_Data[[#This Row],[Details]])),"UPI Expense",IF(ISNUMBER(SEARCH("W TFR",Account_Data[[#This Row],[Details]])),"Transfer","Other"))))))))) -> EMI | I15: =Account_Data[[#This Row],[Credit]]-Account_Data[[#This Row],[Debit]] -> -8704 | J15: =EOMONTH(Account_Data[[#This Row],[Date]],0) -> 45777 | K15: =ABS(Account_Data[[#This Row],[Amount]]) -> 8704
A16: 45754 | B16: DEP TFR NEFT*SCBL*SCBLH*PGIM INDIA M UTU AT | D16: 44060.27 | E16: 72249.74 | F16: =TEXT(Account_Data[[#This Row],[Date]],"mmm-yyyy") -> Apr-2025 | G16: =IF(Account_Data[[#This Row],[Credit]]>0,"Income","Expense") -> Income | H16: =IF(AND(Account_Data[[#This Row],[Credit]]>0,ISNUMBER(SEARCH("TFR",Account_Data[[#This Row],[Details]])),Account_Data[[#This Row],[Credit]]>=200000),"Loan Taken", IF(AND(Account_Data[[#This Row],[Debit]]>0,OR(ISNUMBER(SEARCH("ETMONEY",Account_Data[[#This Row],[Details]])),ISNUMBER(SEARCH("PGIM",Account_Data[[#This Row],[Details]])),ISNUMBER(SEARCH("CANARA",Account_Data[[#This Row],[Details]])))),"Investment (Outflow)", IF(AND(Account_Data[[#This Row],[Credit]]>0,OR(ISNUMBER(SEARCH("PGIM",Account_Data[[#This Row],[Details]])),ISNUMBER(SEARCH("CANARA",Account_Data[[#This Row],[Details]])),ISNUMBER(SEARCH("MUTUAL",Account_Data[[#This Row],[Details]])))),"Investment Return", IF(OR(ISNUMBER(SEARCH("LOAN",Account_Data[[#This Row],[Details]])),ISNUMBER(SEARCH("RECOVERY",Account_Data[[#This Row],[Details]]))),"Loan Payment", IF(OR(ISNUMBER(SEARCH("SALARY",Account_Data[[#This Row],[Details]])),ISNUMBER(SEARCH("EMPLOYER DEP",Account_Data[[#This Row],[Details]]))),"Income", IF(OR(ISNUMBER(SEARCH("ACH",Account_Data[[#This Row],[Details]])),ISNUMBER(SEARCH("DIRECT DR",Account_Data[[#This Row],[Details]]))),"EMI", IF(ISNUMBER(SEARCH("ATM",Account_Data[[#This Row],[Details]])),"Cash", IF(ISNUMBER(SEARCH("UPI",Account_Data[[#This Row],[Details]])),"UPI Expense",IF(ISNUMBER(SEARCH("W TFR",Account_Data[[#This Row],[Details]])),"Transfer","Other"))))))))) -> Investment Return | I16: =Account_Data[[#This Row],[Credit]]-Account_Data[[#This Row],[Debit]] -> 44060.27 | J16: =EOMONTH(Account_Data[[#This Row],[Date]],0) -> 45777 | K16: =ABS(Account_Data[[#This Row],[Amount]]) -> 44060.27
A17: 45754 | B17: DEP TFR NEFT*HDFC*HDFCH*CANARA ROBEC O M AT | D17: 30864.21 | E17: 103113.95 | F17: =TEXT(Account_Data[[#This Row],[Date]],"mmm-yyyy") -> Apr-2025 | G17: =IF(Account_Data[[#This Row],[Credit]]>0,"Income","Expense") -> Income | H17: =IF(AND(Account_Data[[#This Row],[Credit]]>0,ISNUMBER(SEARCH("TFR",Account_Data[[#This Row],[Details]])),Account_Data[[#This Row],[Credit]]>=200000),"Loan Taken", IF(AND(Account_Data[[#This Row],[Debit]]>0,OR(ISNUMBER(SEARCH("ETMONEY",Account_Data[[#This Row],[Details]])),ISNUMBER(SEARCH("PGIM",Account_Data[[#This Row],[Details]])),ISNUMBER(SEARCH("CANARA",Account_Data[[#This Row],[Details]])))),"Investment (Outflow)", IF(AND(Account_Data[[#This Row],[Credit]]>0,OR(ISNUMBER(SEARCH("PGIM",Account_Data[[#This Row],[Details]])),ISNUMBER(SEARCH("CANARA",Account_Data[[#This Row],[Details]])),ISNUMBER(SEARCH("MUTUAL",Account_Data[[#This Row],[Details]])))),"Investment Return", IF(OR(ISNUMBER(SEARCH("LOAN",Account_Data[[#This Row],[Details]])),ISNUMBER(SEARCH("RECOVERY",Account_Data[[#This Row],[Details]]))),"Loan Payment", IF(OR(ISNUMBER(SEARCH("SALARY",Account_Data[[#This Row],[Details]])),ISNUMBER(SEARCH("EMPLOYER DEP",Account_Data[[#This Row],[Details]]))),"Income", IF(OR(ISNUMBER(SEARCH("ACH",Account_Data[[#This Row],[Details]])),ISNUMBER(SEARCH("DIRECT DR",Account_Data[[#This Row],[Details]]))),"EMI", IF(ISNUMBER(SEARCH("ATM",Account_Data[[#This Row],[Details]])),"Cash", IF(ISNUMBER(SEARCH("UPI",Account_Data[[#This Row],[Details]])),"UPI Expense",IF(ISNUMBER(SEARCH("W TFR",Account_Data[[#This Row],[Details]])),"Transfer","Other"))))))))) -> Investment Return | I17: =Account_Data[[#This Row],[Credit]]-Account_Data[[#This Row],[Debit]] -> 30864.21 | J17: =EOMONTH(Account_Data[[#This Row],[Date]],0) -> 45777 | K17: =ABS(Account_Data[[#This Row],[Amount]]) -> 30864.21
A18: 45755 | B18: W TFR SMA OVERDUE RECOVERY OF Mr. XYZ AT | C18: 16329 | E18: 86784.95 | F18: =TEXT(Account_Data[[#This Row],[Date]],"mmm-yyyy") -> Apr-2025 | G18: =IF(Account_Data[[#This Row],[Credit]]>0,"Income","Expense") -> Expense | H18: =IF(AND(Account_Data[[#This Row],[Credit]]>0,ISNUMBER(SEARCH("TFR",Account_Data[[#This Row],[Details]])),Account_Data[[#This Row],[Credit]]>=200000),"Loan Taken", IF(AND(Account_Data[[#This Row],[Debit]]>0,OR(ISNUMBER(SEARCH("ETMONEY",Account_Data[[#This Row],[Details]])),ISNUMBER(SEARCH("PGIM",Account_Data[[#This Row],[Details]])),ISNUMBER(SEARCH("CANARA",Account_Data[[#This Row],[Details]])))),"Investment (Outflow)", IF(AND(Account_Data[[#This Row],[Credit]]>0,OR(ISNUMBER(SEARCH("PGIM",Account_Data[[#This Row],[Details]])),ISNUMBER(SEARCH("CANARA",Account_Data[[#This Row],[Details]])),ISNUMBER(SEARCH("MUTUAL",Account_Data[[#This Row],[Details]])))),"Investment Return", IF(OR(ISNUMBER(SEARCH("LOAN",Account_Data[[#This Row],[Details]])),ISNUMBER(SEARCH("RECOVERY",Account_Data[[#This Row],[Details]]))),"Loan Payment", IF(OR(ISNUMBER(SEARCH("SALARY",Account_Data[[#This Row],[Details]])),ISNUMBER(SEARCH("EMPLOYER DEP",Account_Data[[#This Row],[Details]]))),"Income", IF(OR(ISNUMBER(SEARCH("ACH",Account_Data[[#This Row],[Details]])),ISNUMBER(SEARCH("DIRECT DR",Account_Data[[#This Row],[Details]]))),"EMI", IF(ISNUMBER(SEARCH("ATM",Account_Data[[#This Row],[Details]])),"Cash", IF(ISNUMBER(SEARCH("UPI",Account_Data[[#This Row],[Details]])),"UPI Expense",IF(ISNUMBER(SEARCH("W TFR",Account_Data[[#This Row],[Details]])),"Transfer","Other"))))))))) -> Loan Payment | I18: =Account_Data[[#This Row],[Credit]]-Account_Data[[#This Row],[Debit]] -> -16329 | J18: =EOMONTH(Account_Data[[#This Row],[Date]],0) -> 45777 | K18: =ABS(Account_Data[[#This Row],[Amount]]) -> 16329
A19: 45756 | B19: W TFR UPI/DR//SOMAN T/YESB/paytmqrx/Pa yme AT | C19: 450 | E19: 86334.95 | F19: =TEXT(Account_Data[[#This Row],[Date]],"mmm-yyyy") -> Apr-2025 | G19: =IF(Account_Data[[#This Row],[Credit]]>0,"Income","Expense") -> Expense | H19: =IF(AND(Account_Data[[#This Row],[Credit]]>0,ISNUMBER(SEARCH("TFR",Account_Data[[#This Row],[Details]])),Account_Data[[#This Row],[Credit]]>=200000),"Loan Taken", IF(AND(Account_Data[[#This Row],[Debit]]>0,OR(ISNUMBER(SEARCH("ETMONEY",Account_Data[[#This Row],[Details]])),ISNUMBER(SEARCH("PGIM",Account_Data[[#This Row],[Details]])),ISNUMBER(SEARCH("CANARA",Account_Data[[#This Row],[Details]])))),"Investment (Outflow)", IF(AND(Account_Data[[#This Row],[Credit]]>0,OR(ISNUMBER(SEARCH("PGIM",Account_Data[[#This Row],[Details]])),ISNUMBER(SEARCH("CANARA",Account_Data[[#This Row],[Details]])),ISNUMBER(SEARCH("MUTUAL",Account_Data[[#This Row],[Details]])))),"Investment Return", IF(OR(ISNUMBER(SEARCH("LOAN",Account_Data[[#This Row],[Details]])),ISNUMBER(SEARCH("RECOVERY",Account_Data[[#This Row],[Details]]))),"Loan Payment", IF(OR(ISNUMBER(SEARCH("SALARY",Account_Data[[#This Row],[Details]])),ISNUMBER(SEARCH("EMPLOYER DEP",Account_Data[[#This Row],[Details]]))),"Income", IF(OR(ISNUMBER(SEARCH("ACH",Account_Data[[#This Row],[Details]])),ISNUMBER(SEARCH("DIRECT DR",Account_Data[[#This Row],[Details]]))),"EMI", IF(ISNUMBER(SEARCH("ATM",Account_Data[[#This Row],[Details]])),"Cash", IF(ISNUMBER(SEARCH("UPI",Account_Data[[#This Row],[Details]])),"UPI Expense",IF(ISNUMBER(SEARCH("W TFR",Account_Data[[#This Row],[Details]])),"Transfer","Other"))))))))) -> UPI Expense | I19: =Account_Data[[#This Row],[Credit]]-Account_Data[[#This Row],[Debit]] -> -450 | J19: =EOMONTH(Account_Data[[#This Row],[Date]],0) -> 45777 | K19: =ABS(Account_Data[[#This Row],[Amount]]) -> 450
A20: 45757 | B20: W TFR UPI/DR//Bank Acc/BARB//P aym AT | C20: 66500 | E20: 19834.95 | F20: =TEXT(Account_Data[[#This Row],[Date]],"mmm-yyyy") -> Apr-2025 | G20: =IF(Account_Data[[#This Row],[Credit]]>0,"Income","Expense") -> Expense | H20: =IF(AND(Account_Data[[#This Row],[Credit]]>0,ISNUMBER(SEARCH("TFR",Account_Data[[#This Row],[Details]])),Account_Data[[#This Row],[Credit]]>=200000),"Loan Taken", IF(AND(Account_Data[[#This Row],[Debit]]>0,OR(ISNUMBER(SEARCH("ETMONEY",Account_Data[[#This Row],[Details]])),ISNUMBER(SEARCH("PGIM",Account_Data[[#This Row],[Details]])),ISNUMBER(SEARCH("CANARA",Account_Data[[#This Row],[Details]])))),"Investment (Outflow)", IF(AND(Account_Data[[#This Row],[Credit]]>0,OR(ISNUMBER(SEARCH("PGIM",Account_Data[[#This Row],[Details]])),ISNUMBER(SEARCH("CANARA",Account_Data[[#This Row],[Details]])),ISNUMBER(SEARCH("MUTUAL",Account_Data[[#This Row],[Details]])))),"Investment Return", IF(OR(ISNUMBER(SEARCH("LOAN",Account_Data[[#This Row],[Details]])),ISNUMBER(SEARCH("RECOVERY",Account_Data[[#This Row],[Details]]))),"Loan Payment", IF(OR(ISNUMBER(SEARCH("SALARY",Account_Data[[#This Row],[Details]])),ISNUMBER(SEARCH("EMPLOYER DEP",Account_Data[[#This Row],[Details]]))),"Income", IF(OR(ISNUMBER(SEARCH("ACH",Account_Data[[#This Row],[Details]])),ISNUMBER(SEARCH("DIRECT DR",Account_Data[[#This Row],[Details]]))),"EMI", IF(ISNUMBER(SEARCH("ATM",Account_Data[[#This Row],[Details]])),"Cash", IF(ISNUMBER(SEARCH("UPI",Account_Data[[#This Row],[Details]])),"UPI Expense",IF(ISNUMBER(SEARCH("W TFR",Account_Data[[#This Row],[Details]])),"Transfer","Other"))))))))) -> UPI Expense | I20: =Account_Data[[#This Row],[Credit]]-Account_Data[[#This Row],[Debit]] -> -66500 | J20: =EOMONTH(Account_Data[[#This Row],[Date]],0) -> 45777 | K20: =ABS(Account_Data[[#This Row],[Amount]]) -> 66500
A21: 45758 | B21: DEP TFR PABFC IOCL LPG SUBSIDY IOAPD AT | D21: 59.52 | E21: 19894.47 | F21: =TEXT(Account_Data[[#This Row],[Date]],"mmm-yyyy") -> Apr-2025 | G21: =IF(Account_Data[[#This Row],[Credit]]>0,"Income","Expense") -> Income | H21: =IF(AND(Account_Data[[#This Row],[Credit]]>0,ISNUMBER(SEARCH("TFR",Account_Data[[#This Row],[Details]])),Account_Data[[#This Row],[Credit]]>=200000),"Loan Taken", IF(AND(Account_Data[[#This Row],[Debit]]>0,OR(ISNUMBER(SEARCH("ETMONEY",Account_Data[[#This Row],[Details]])),ISNUMBER(SEARCH("PGIM",Account_Data[[#This Row],[Details]])),ISNUMBER(SEARCH("CANARA",Account_Data[[#This Row],[Details]])))),"Investment (Outflow)", IF(AND(Account_Data[[#This Row],[Credit]]>0,OR(ISNUMBER(SEARCH("PGIM",Account_Data[[#This Row],[Details]])),ISNUMBER(SEARCH("CANARA",Account_Data[[#This Row],[Details]])),ISNUMBER(SEARCH("MUTUAL",Account_Data[[#This Row],[Details]])))),"Investment Return", IF(OR(ISNUMBER(SEARCH("LOAN",Account_Data[[#This Row],[Details]])),ISNUMBER(SEARCH("RECOVERY",Account_Data[[#This Row],[Details]]))),"Loan Payment", IF(OR(ISNUMBER(SEARCH("SALARY",Account_Data[[#This Row],[Details]])),ISNUMBER(SEARCH("EMPLOYER DEP",Account_Data[[#This Row],[Details]]))),"Income", IF(OR(ISNUMBER(SEARCH("ACH",Account_Data[[#This Row],[Details]])),ISNUMBER(SEARCH("DIRECT DR",Account_Data[[#This Row],[Details]]))),"EMI", IF(ISNUMBER(SEARCH("ATM",Account_Data[[#This Row],[Details]])),"Cash", IF(ISNUMBER(SEARCH("UPI",Account_Data[[#This Row],[Details]])),"UPI Expense",IF(ISNUMBER(SEARCH("W TFR",Account_Data[[#This Row],[Details]])),"Transfer","Other"))))))))) -> Other | I21: =Account_Data[[#This Row],[Credit]]-Account_Data[[#This Row],[Debit]] -> 59.52 | J21: =EOMONTH(Account_Data[[#This Row],[Date]],0) -> 45777 | K21: =ABS(Account_Data[[#This Row],[Amount]]) -> 59.52
A22: 45758 | B22: W TFR UPI/DR//Pranjal /SBIN/pranjalsin/P aym AT | C22: 1219 | E22: 18675.47 | F22: =TEXT(Account_Data[[#This Row],[Date]],"mmm-yyyy") -> Apr-2025 | G22: =IF(Account_Data[[#This Row],[Credit]]>0,"Income","Expense") -> Expense | H22: =IF(AND(Account_Data[[#This Row],[Credit]]>0,ISNUMBER(SEARCH("TFR",Account_Data[[#This Row],[Details]])),Account_Data[[#This Row],[Credit]]>=200000),"Loan Taken", IF(AND(Account_Data[[#This Row],[Debit]]>0,OR(ISNUMBER(SEARCH("ETMONEY",Account_Data[[#This Row],[Details]])),ISNUMBER(SEARCH("PGIM",Account_Data[[#This Row],[Details]])),ISNUMBER(SEARCH("CANARA",Account_Data[[#This Row],[Details]])))),"Investment (Outflow)", IF(AND(Account_Data[[#This Row],[Credit]]>0,OR(ISNUMBER(SEARCH("PGIM",Account_Data[[#This Row],[Details]])),ISNUMBER(SEARCH("CANARA",Account_Data[[#This Row],[Details]])),ISNUMBER(SEARCH("MUTUAL",Account_Data[[#This Row],[Details]])))),"Investment Return", IF(OR(ISNUMBER(SEARCH("LOAN",Account_Data[[#This Row],[Details]])),ISNUMBER(SEARCH("RECOVERY",Account_Data[[#This Row],[Details]]))),"Loan Payment", IF(OR(ISNUMBER(SEARCH("SALARY",Account_Data[[#This Row],[Details]])),ISNUMBER(SEARCH("EMPLOYER DEP",Account_Data[[#This Row],[Details]]))),"Income", IF(OR(ISNUMBER(SEARCH("ACH",Account_Data[[#This Row],[Details]])),ISNUMBER(SEARCH("DIRECT DR",Account_Data[[#This Row],[Details]]))),"EMI", IF(ISNUMBER(SEARCH("ATM",Account_Data[[#This Row],[Details]])),"Cash", IF(ISNUMBER(SEARCH("UPI",Account_Data[[#This Row],[Details]])),"UPI Expense",IF(ISNUMBER(SEARCH("W TFR",Account_Data[[#This Row],[Details]])),"Transfer","Other"))))))))) -> UPI Expense | I22: =Account_Data[[#This Row],[Credit]]-Account_Data[[#This Row],[Debit]] -> -1219 | J22: =EOMONTH(Account_Data[[#This Row],[Date]],0) -> 45777 | K22: =ABS(Account_Data[[#This Row],[Amount]]) -> 1219
A23: 45758 | B23: W TFR UPI/DR//SOMAN T/YESB/paytmqrx/Pa yme AT | C23: 260 | E23: 18415.47 | F23: =TEXT(Account_Data[[#This Row],[Date]],"mmm-yyyy") -> Apr-2025 | G23: =IF(Account_Data[[#This Row],[Credit]]>0,"Income","Expense") -> Expense | H23: =IF(AND(Account_Data[[#This Row],[Credit]]>0,ISNUMBER(SEARCH("TFR",Account_Data[[#This Row],[Details]])),Account_Data[[#This Row],[Credit]]>=200000),"Loan Taken", IF(AND(Account_Data[[#This Row],[Debit]]>0,OR(ISNUMBER(SEARCH("ETMONEY",Account_Data[[#This Row],[Details]])),ISNUMBER(SEARCH("PGIM",Account_Data[[#This Row],[Details]])),ISNUMBER(SEARCH("CANARA",Account_Data[[#This Row],[Details]])))),"Investment (Outflow)", IF(AND(Account_Data[[#This Row],[Credit]]>0,OR(ISNUMBER(SEARCH("PGIM",Account_Data[[#This Row],[Details]])),ISNUMBER(SEARCH("CANARA",Account_Data[[#This Row],[Details]])),ISNUMBER(SEARCH("MUTUAL",Account_Data[[#This Row],[Details]])))),"Investment Return", IF(OR(ISNUMBER(SEARCH("LOAN",Account_Data[[#This Row],[Details]])),ISNUMBER(SEARCH("RECOVERY",Account_Data[[#This Row],[Details]]))),"Loan Payment", IF(OR(ISNUMBER(SEARCH("SALARY",Account_Data[[#This Row],[Details]])),ISNUMBER(SEARCH("EMPLOYER DEP",Account_Data[[#This Row],[Details]]))),"Income", IF(OR(ISNUMBER(SEARCH("ACH",Account_Data[[#This Row],[Details]])),ISNUMBER(SEARCH("DIRECT DR",Account_Data[[#This Row],[Details]]))),"EMI", IF(ISNUMBER(SEARCH("ATM",Account_Data[[#This Row],[Details]])),"Cash", IF(ISNUMBER(SEARCH("UPI",Account_Data[[#This Row],[Details]])),"UPI Expense",IF(ISNUMBER(SEARCH("W TFR",Account_Data[[#This Row],[Details]])),"Transfer","Other"))))))))) -> UPI Expense | I23: =Account_Data[[#This Row],[Credit]]-Account_Data[[#This Row],[Debit]] -> -260 | J23: =EOMONTH(Account_Data[[#This Row],[Date]],0) -> 45777 | K23: =ABS(Account_Data[[#This Row],[Amount]]) -> 260
A24: 45758 | B24: W TFR UPI/DR//DHIRENDR/SBIN//P aym AT | C24: 350 | E24: 18065.47 | F24: =TEXT(Account_Data[[#This Row],[Date]],"mmm-yyyy") -> Apr-2025 | G24: =IF(Account_Data[[#This Row],[Credit]]>0,"Income","Expense") -> Expense | H24: =IF(AND(Account_Data[[#This Row],[Credit]]>0,ISNUMBER(SEARCH("TFR",Account_Data[[#This Row],[Details]])),Account_Data[[#This Row],[Credit]]>=200000),"Loan Taken", IF(AND(Account_Data[[#This Row],[Debit]]>0,OR(ISNUMBER(SEARCH("ETMONEY",Account_Data[[#This Row],[Details]])),ISNUMBER(SEARCH("PGIM",Account_Data[[#This Row],[Details]])),ISNUMBER(SEARCH("CANARA",Account_Data[[#This Row],[Details]])))),"Investment (Outflow)", IF(AND(Account_Data[[#This Row],[Credit]]>0,OR(ISNUMBER(SEARCH("PGIM",Account_Data[[#This Row],[Details]])),ISNUMBER(SEARCH("CANARA",Account_Data[[#This Row],[Details]])),ISNUMBER(SEARCH("MUTUAL",Account_Data[[#This Row],[Details]])))),"Investment Return", IF(OR(ISNUMBER(SEARCH("LOAN",Account_Data[[#This Row],[Details]])),ISNUMBER(SEARCH("RECOVERY",Account_Data[[#This Row],[Details]]))),"Loan Payment", IF(OR(ISNUMBER(SEARCH("SALARY",Account_Data[[#This Row],[Details]])),ISNUMBER(SEARCH("EMPLOYER DEP",Account_Data[[#This Row],[Details]]))),"Income", IF(OR(ISNUMBER(SEARCH("ACH",Account_Data[[#This Row],[Details]])),ISNUMBER(SEARCH("DIRECT DR",Account_Data[[#This Row],[Details]]))),"EMI", IF(ISNUMBER(SEARCH("ATM",Account_Data[[#This Row],[Details]])),"Cash", IF(ISNUMBER(SEARCH("UPI",Account_Data[[#This Row],[Details]])),"UPI Expense",IF(ISNUMBER(SEARCH("W TFR",Account_Data[[#This Row],[Details]])),"Transfer","Other"))))))))) -> UPI Expense | I24: =Account_Data[[#This Row],[Credit]]-Account_Data[[#This Row],[Debit]] -> -350 | J24: =EOMONTH(Account_Data[[#This Row],[Date]],0) -> 45777 | K24: =ABS(Account_Data[[#This Row],[Amount]]) -> 350
A25: 45759 | B25: W TFR UPI/DR//PANKAJ K/SBIN/pankajmish/ PAY AT | C25: 500 | E25: 17565.47 | F25: =TEXT(Account_Data[[#This Row],[Date]],"mmm-yyyy") -> Apr-2025 | G25: =IF(Account_Data[[#This Row],[Credit]]>0,"Income","Expense") -> Expense | H25: =IF(AND(Account_Data[[#This Row],[Credit]]>0,ISNUMBER(SEARCH("TFR",Account_Data[[#This Row],[Details]])),Account_Data[[#This Row],[Credit]]>=200000),"Loan Taken", IF(AND(Account_Data[[#This Row],[Debit]]>0,OR(ISNUMBER(SEARCH("ETMONEY",Account_Data[[#This Row],[Details]])),ISNUMBER(SEARCH("PGIM",Account_Data[[#This Row],[Details]])),ISNUMBER(SEARCH("CANARA",Account_Data[[#This Row],[Details]])))),"Investment (Outflow)", IF(AND(Account_Data[[#This Row],[Credit]]>0,OR(ISNUMBER(SEARCH("PGIM",Account_Data[[#This Row],[Details]])),ISNUMBER(SEARCH("CANARA",Account_Data[[#This Row],[Details]])),ISNUMBER(SEARCH("MUTUAL",Account_Data[[#This Row],[Details]])))),"Investment Return", IF(OR(ISNUMBER(SEARCH("LOAN",Account_Data[[#This Row],[Details]])),ISNUMBER(SEARCH("RECOVERY",Account_Data[[#This Row],[Details]]))),"Loan Payment", IF(OR(ISNUMBER(SEARCH("SALARY",Account_Data[[#This Row],[Details]])),ISNUMBER(SEARCH("EMPLOYER DEP",Account_Data[[#This Row],[Details]]))),"Income", IF(OR(ISNUMBER(SEARCH("ACH",Account_Data[[#This Row],[Details]])),ISNUMBER(SEARCH("DIRECT DR",Account_Data[[#This Row],[Details]]))),"EMI", IF(ISNUMBER(SEARCH("ATM",Account_Data[[#This Row],[Details]])),"Cash", IF(ISNUMBER(SEARCH("UPI",Account_Data[[#This Row],[Details]])),"UPI Expense",IF(ISNUMBER(SEARCH("W TFR",Account_Data[[#This Row],[Details]])),"Transfer","Other"))))))))) -> UPI Expense | I25: =Account_Data[[#This Row],[Credit]]-Account_Data[[#This Row],[Debit]] -> -500 | J25: =EOMONTH(Account_Data[[#This Row],[Date]],0) -> 45777 | K25: =ABS(Account_Data[[#This Row],[Amount]]) -> 500
A26: 45759 | B26: W TFR UPI/DR//AFJALANS/YESB/Q/P aym AT | C26: 5 | E26: 17560.47 | F26: =TEXT(Account_Data[[#This Row],[Date]],"mmm-yyyy") -> Apr-2025 | G26: =IF(Account_Data[[#This Row],[Credit]]>0,"Income","Expense") -> Expense | H26: =IF(AND(Account_Data[[#This Row],[Credit]]>0,ISNUMBER(SEARCH("TFR",Account_Data[[#This Row],[Details]])),Account_Data[[#This Row],[Credit]]>=200000),"Loan Taken", IF(AND(Account_Data[[#This Row],[Debit]]>0,OR(ISNUMBER(SEARCH("ETMONEY",Account_Data[[#This Row],[Details]])),ISNUMBER(SEARCH("PGIM",Account_Data[[#This Row],[Details]])),ISNUMBER(SEARCH("CANARA",Account_Data[[#This Row],[Details]])))),"Investment (Outflow)", IF(AND(Account_Data[[#This Row],[Credit]]>0,OR(ISNUMBER(SEARCH("PGIM",Account_Data[[#This Row],[Details]])),ISNUMBER(SEARCH("CANARA",Account_Data[[#This Row],[Details]])),ISNUMBER(SEARCH("MUTUAL",Account_Data[[#This Row],[Details]])))),"Investment Return", IF(OR(ISNUMBER(SEARCH("LOAN",Account_Data[[#This Row],[Details]])),ISNUMBER(SEARCH("RECOVERY",Account_Data[[#This Row],[Details]]))),"Loan Payment", IF(OR(ISNUMBER(SEARCH("SALARY",Account_Data[[#This Row],[Details]])),ISNUMBER(SEARCH("EMPLOYER DEP",Account_Data[[#This Row],[Details]]))),"Income", IF(OR(ISNUMBER(SEARCH("ACH",Account_Data[[#This Row],[Details]])),ISNUMBER(SEARCH("DIRECT DR",Account_Data[[#This Row],[Details]]))),"EMI", IF(ISNUMBER(SEARCH("ATM",Account_Data[[#This Row],[Details]])),"Cash", IF(ISNUMBER(SEARCH("UPI",Account_Data[[#This Row],[Details]])),"UPI Expense",IF(ISNUMBER(SEARCH("W TFR",Account_Data[[#This Row],[Details]])),"Transfer","Other"))))))))) -> UPI Expense | I26: =Account_Data[[#This Row],[Credit]]-Account_Data[[#This Row],[Debit]] -> -5 | J26: =EOMONTH(Account_Data[[#This Row],[Date]],0) -> 45777 | K26: =ABS(Account_Data[[#This Row],[Amount]]) -> 5
A27: 45760 | B27: W TFR UPI/DR//NALIN SI/DBSS/nalinbisen/ PAY AT | C27: 424 | E27: 17136.47 | F27: =TEXT(Account_Data[[#This Row],[Date]],"mmm-yyyy") -> Apr-2025 | G27: =IF(Account_Data[[#This Row],[Credit]]>0,"Income","Expense") -> Expense | H27: =IF(AND(Account_Data[[#This Row],[Credit]]>0,ISNUMBER(SEARCH("TFR",Account_Data[[#This Row],[Details]])),Account_Data[[#This Row],[Credit]]>=200000),"Loan Taken", IF(AND(Account_Data[[#This Row],[Debit]]>0,OR(ISNUMBER(SEARCH("ETMONEY",Account_Data[[#This Row],[Details]])),ISNUMBER(SEARCH("PGIM",Account_Data[[#This Row],[Details]])),ISNUMBER(SEARCH("CANARA",Account_Data[[#This Row],[Details]])))),"Investment (Outflow)", IF(AND(Account_Data[[#This Row],[Credit]]>0,OR(ISNUMBER(SEARCH("PGIM",Account_Data[[#This Row],[Details]])),ISNUMBER(SEARCH("CANARA",Account_Data[[#This Row],[Details]])),ISNUMBER(SEARCH("MUTUAL",Account_Data[[#This Row],[Details]])))),"Investment Return", IF(OR(ISNUMBER(SEARCH("LOAN",Account_Data[[#This Row],[Details]])),ISNUMBER(SEARCH("RECOVERY",Account_Data[[#This Row],[Details]]))),"Loan Payment", IF(OR(ISNUMBER(SEARCH("SALARY",Account_Data[[#This Row],[Details]])),ISNUMBER(SEARCH("EMPLOYER DEP",Account_Data[[#This Row],[Details]]))),"Income", IF(OR(ISNUMBER(SEARCH("ACH",Account_Data[[#This Row],[Details]])),ISNUMBER(SEARCH("DIRECT DR",Account_Data[[#This Row],[Details]]))),"EMI", IF(ISNUMBER(SEARCH("ATM",Account_Data[[#This Row],[Details]])),"Cash", IF(ISNUMBER(SEARCH("UPI",Account_Data[[#This Row],[Details]])),"UPI Expense",IF(ISNUMBER(SEARCH("W TFR",Account_Data[[#This Row],[Details]])),"Transfer","Other"))))))))) -> UPI Expense | I27: =Account_Data[[#This Row],[Credit]]-Account_Data[[#This Row],[Debit]] -> -424 | J27: =EOMONTH(Account_Data[[#This Row],[Date]],0) -> 45777 | K27: =ABS(Account_Data[[#This Row],[Amount]]) -> 424
A28: 45760 | B28: W TFR UPI/DR//KESHAVA /YESB/paytmqr/P aym AT | C28: 2000 | E28: 15136.47 | F28: =TEXT(Account_Data[[#This Row],[Date]],"mmm-yyyy") -> Apr-2025 | G28: =IF(Account_Data[[#This Row],[Credit]]>0,"Income","Expense") -> Expense | H28: =IF(AND(Account_Data[[#This Row],[Credit]]>0,ISNUMBER(SEARCH("TFR",Account_Data[[#This Row],[Details]])),Account_Data[[#This Row],[Credit]]>=200000),"Loan Taken", IF(AND(Account_Data[[#This Row],[Debit]]>0,OR(ISNUMBER(SEARCH("ETMONEY",Account_Data[[#This Row],[Details]])),ISNUMBER(SEARCH("PGIM",Account_Data[[#This Row],[Details]])),ISNUMBER(SEARCH("CANARA",Account_Data[[#This Row],[Details]])))),"Investment (Outflow)", IF(AND(Account_Data[[#This Row],[Credit]]>0,OR(ISNUMBER(SEARCH("PGIM",Account_Data[[#This Row],[Details]])),ISNUMBER(SEARCH("CANARA",Account_Data[[#This Row],[Details]])),ISNUMBER(SEARCH("MUTUAL",Account_Data[[#This Row],[Details]])))),"Investment Return", IF(OR(ISNUMBER(SEARCH("LOAN",Account_Data[[#This Row],[Details]])),ISNUMBER(SEARCH("RECOVERY",Account_Data[[#This Row],[Details]]))),"Loan Payment", IF(OR(ISNUMBER(SEARCH("SALARY",Account_Data[[#This Row],[Details]])),ISNUMBER(SEARCH("EMPLOYER DEP",Account_Data[[#This Row],[Details]]))),"Income", IF(OR(ISNUMBER(SEARCH("ACH",Account_Data[[#This Row],[Details]])),ISNUMBER(SEARCH("DIRECT DR",Account_Data[[#This Row],[Details]]))),"EMI", IF(ISNUMBER(SEARCH("ATM",Account_Data[[#This Row],[Details]])),"Cash", IF(ISNUMBER(SEARCH("UPI",Account_Data[[#This Row],[Details]])),"UPI Expense",IF(ISNUMBER(SEARCH("W TFR",Account_Data[[#This Row],[Details]])),"Transfer","Other"))))))))) -> UPI Expense | I28: =Account_Data[[#This Row],[Credit]]-Account_Data[[#This Row],[Debit]] -> -2000 | J28: =EOMONTH(Account_Data[[#This Row],[Date]],0) -> 45777 | K28: =ABS(Account_Data[[#This Row],[Amount]]) -> 2000
A29: 45760 | B29: W TFR UPI/DR//Apex hea/UTIB/gpay-/P aym AT | C29: 400 | E29: 14736.47 | F29: =TEXT(Account_Data[[#This Row],[Date]],"mmm-yyyy") -> Apr-2025 | G29: =IF(Account_Data[[#This Row],[Credit]]>0,"Income","Expense") -> Expense | H29: =IF(AND(Account_Data[[#This Row],[Credit]]>0,ISNUMBER(SEARCH("TFR",Account_Data[[#This Row],[Details]])),Account_Data[[#This Row],[Credit]]>=200000),"Loan Taken", IF(AND(Account_Data[[#This Row],[Debit]]>0,OR(ISNUMBER(SEARCH("ETMONEY",Account_Data[[#This Row],[Details]])),ISNUMBER(SEARCH("PGIM",Account_Data[[#This Row],[Details]])),ISNUMBER(SEARCH("CANARA",Account_Data[[#This Row],[Details]])))),"Investment (Outflow)", IF(AND(Account_Data[[#This Row],[Credit]]>0,OR(ISNUMBER(SEARCH("PGIM",Account_Data[[#This Row],[Details]])),ISNUMBER(SEARCH("CANARA",Account_Data[[#This Row],[Details]])),ISNUMBER(SEARCH("MUTUAL",Account_Data[[#This Row],[Details]])))),"Investment Return", IF(OR(ISNUMBER(SEARCH("LOAN",Account_Data[[#This Row],[Details]])),ISNUMBER(SEARCH("RECOVERY",Account_Data[[#This Row],[Details]]))),"Loan Payment", IF(OR(ISNUMBER(SEARCH("SALARY",Account_Data[[#This Row],[Details]])),ISNUMBER(SEARCH("EMPLOYER DEP",Account_Data[[#This Row],[Details]]))),"Income", IF(OR(ISNUMBER(SEARCH("ACH",Account_Data[[#This Row],[Details]])),ISNUMBER(SEARCH("DIRECT DR",Account_Data[[#This Row],[Details]]))),"EMI", IF(ISNUMBER(SEARCH("ATM",Account_Data[[#This Row],[Details]])),"Cash", IF(ISNUMBER(SEARCH("UPI",Account_Data[[#This Row],[Details]])),"UPI Expense",IF(ISNUMBER(SEARCH("W TFR",Account_Data[[#This Row],[Details]])),"Transfer","Other"))))))))) -> UPI Expense | I29: =Account_Data[[#This Row],[Credit]]-Account_Data[[#This Row],[Debit]] -> -400 | J29: =EOMONTH(Account_Data[[#This Row],[Date]],0) -> 45777 | K29: =ABS(Account_Data[[#This Row],[Amount]]) -> 400
A30: 45760 | B30: W TFR UPI/DR//Apex hea/UTIB/gpay-/P aym AT | C30: 252 | E30: 14484.47 | F30: =TEXT(Account_Data[[#This Row],[Date]],"mmm-yyyy") -> Apr-2025 | G30: =IF(Account_Data[[#This Row],[Credit]]>0,"Income","Expense") -> Expense | H30: =IF(AND(Account_Data[[#This Row],[Credit]]>0,ISNUMBER(SEARCH("TFR",Account_Data[[#This Row],[Details]])),Account_Data[[#This Row],[Credit]]>=200000),"Loan Taken", IF(AND(Account_Data[[#This Row],[Debit]]>0,OR(ISNUMBER(SEARCH("ETMONEY",Account_Data[[#This Row],[Details]])),ISNUMBER(SEARCH("PGIM",Account_Data[[#This Row],[Details]])),ISNUMBER(SEARCH("CANARA",Account_Data[[#This Row],[Details]])))),"Investment (Outflow)", IF(AND(Account_Data[[#This Row],[Credit]]>0,OR(ISNUMBER(SEARCH("PGIM",Account_Data[[#This Row],[Details]])),ISNUMBER(SEARCH("CANARA",Account_Data[[#This Row],[Details]])),ISNUMBER(SEARCH("MUTUAL",Account_Data[[#This Row],[Details]])))),"Investment Return", IF(OR(ISNUMBER(SEARCH("LOAN",Account_Data[[#This Row],[Details]])),ISNUMBER(SEARCH("RECOVERY",Account_Data[[#This Row],[Details]]))),"Loan Payment", IF(OR(ISNUMBER(SEARCH("SALARY",Account_Data[[#This Row],[Details]])),ISNUMBER(SEARCH("EMPLOYER DEP",Account_Data[[#This Row],[Details]]))),"Income", IF(OR(ISNUMBER(SEARCH("ACH",Account_Data[[#This Row],[Details]])),ISNUMBER(SEARCH("DIRECT DR",Account_Data[[#This Row],[Details]]))),"EMI", IF(ISNUMBER(SEARCH("ATM",Account_Data[[#This Row],[Details]])),"Cash", IF(ISNUMBER(SEARCH("UPI",Account_Data[[#This Row],[Details]])),"UPI Expense",IF(ISNUMBER(SEARCH("W TFR",Account_Data[[#This Row],[Details]])),"Transfer","Other"))))))))) -> UPI Expense | I30: =Account_Data[[#This Row],[Credit]]-Account_Data[[#This Row],[Debit]] -> -252 | J30: =EOMONTH(Account_Data[[#This Row],[Date]],0) -> 45777 | K30: =ABS(Account_Data[[#This Row],[Amount]]) -> 252
A31: 45761 | B31: ATM W ATM CASH ATM SADAR PRATAPGARH | C31: 7000 | E31: 7484.47 | F31: =TEXT(Account_Data[[#This Row],[Date]],"mmm-yyyy") -> Apr-2025 | G31: =IF(Account_Data[[#This Row],[Credit]]>0,"Income","Expense") -> Expense | H31: =IF(AND(Account_Data[[#This Row],[Credit]]>0,ISNUMBER(SEARCH("TFR",Account_Data[[#This Row],[Details]])),Account_Data[[#This Row],[Credit]]>=200000),"Loan Taken", IF(AND(Account_Data[[#This Row],[Debit]]>0,OR(ISNUMBER(SEARCH("ETMONEY",Account_Data[[#This Row],[Details]])),ISNUMBER(SEARCH("PGIM",Account_Data[[#This Row],[Details]])),ISNUMBER(SEARCH("CANARA",Account_Data[[#This Row],[Details]])))),"Investment (Outflow)", IF(AND(Account_Data[[#This Row],[Credit]]>0,OR(ISNUMBER(SEARCH("PGIM",Account_Data[[#This Row],[Details]])),ISNUMBER(SEARCH("CANARA",Account_Data[[#This Row],[Details]])),ISNUMBER(SEARCH("MUTUAL",Account_Data[[#This Row],[Details]])))),"Investment Return", IF(OR(ISNUMBER(SEARCH("LOAN",Account_Data[[#This Row],[Details]])),ISNUMBER(SEARCH("RECOVERY",Account_Data[[#This Row],[Details]]))),"Loan Payment", IF(OR(ISNUMBER(SEARCH("SALARY",Account_Data[[#This Row],[Details]])),ISNUMBER(SEARCH("EMPLOYER DEP",Account_Data[[#This Row],[Details]]))),"Income", IF(OR(ISNUMBER(SEARCH("ACH",Account_Data[[#This Row],[Details]])),ISNUMBER(SEARCH("DIRECT DR",Account_Data[[#This Row],[Details]]))),"EMI", IF(ISNUMBER(SEARCH("ATM",Account_Data[[#This Row],[Details]])),"Cash", IF(ISNUMBER(SEARCH("UPI",Account_Data[[#This Row],[Details]])),"UPI Expense",IF(ISNUMBER(SEARCH("W TFR",Account_Data[[#This Row],[Details]])),"Transfer","Other"))))))))) -> Cash | I31: =Account_Data[[#This Row],[Credit]]-Account_Data[[#This Row],[Debit]] -> -7000 | J31: =EOMONTH(Account_Data[[#This Row],[Date]],0) -> 45777 | K31: =ABS(Account_Data[[#This Row],[Amount]]) -> 7000
A32: 45761 | B32: W TFR UPI/DR//PRAKASH /YESB/paytmqrr/P aym AT | C32: 851 | E32: 6633.47 | F32: =TEXT(Account_Data[[#This Row],[Date]],"mmm-yyyy") -> Apr-2025 | G32: =IF(Account_Data[[#This Row],[Credit]]>0,"Income","Expense") -> Expense | H32: =IF(AND(Account_Data[[#This Row],[Credit]]>0,ISNUMBER(SEARCH("TFR",Account_Data[[#This Row],[Details]])),Account_Data[[#This Row],[Credit]]>=200000),"Loan Taken", IF(AND(Account_Data[[#This Row],[Debit]]>0,OR(ISNUMBER(SEARCH("ETMONEY",Account_Data[[#This Row],[Details]])),ISNUMBER(SEARCH("PGIM",Account_Data[[#This Row],[Details]])),ISNUMBER(SEARCH("CANARA",Account_Data[[#This Row],[Details]])))),"Investment (Outflow)", IF(AND(Account_Data[[#This Row],[Credit]]>0,OR(ISNUMBER(SEARCH("PGIM",Account_Data[[#This Row],[Details]])),ISNUMBER(SEARCH("CANARA",Account_Data[[#This Row],[Details]])),ISNUMBER(SEARCH("MUTUAL",Account_Data[[#This Row],[Details]])))),"Investment Return", IF(OR(ISNUMBER(SEARCH("LOAN",Account_Data[[#This Row],[Details]])),ISNUMBER(SEARCH("RECOVERY",Account_Data[[#This Row],[Details]]))),"Loan Payment", IF(OR(ISNUMBER(SEARCH("SALARY",Account_Data[[#This Row],[Details]])),ISNUMBER(SEARCH("EMPLOYER DEP",Account_Data[[#This Row],[Details]]))),"Income", IF(OR(ISNUMBER(SEARCH("ACH",Account_Data[[#This Row],[Details]])),ISNUMBER(SEARCH("DIRECT DR",Account_Data[[#This Row],[Details]]))),"EMI", IF(ISNUMBER(SEARCH("ATM",Account_Data[[#This Row],[Details]])),"Cash", IF(ISNUMBER(SEARCH("UPI",Account_Data[[#This Row],[Details]])),"UPI Expense",IF(ISNUMBER(SEARCH("W TFR",Account_Data[[#This Row],[Details]])),"Transfer","Other"))))))))) -> UPI Expense | I32: =Account_Data[[#This Row],[Credit]]-Account_Data[[#This Row],[Debit]] -> -851 | J32: =EOMONTH(Account_Data[[#This Row],[Date]],0) -> 45777 | K32: =ABS(Account_Data[[#This Row],[Amount]]) -> 851
A33: 45761 | B33: W TFR UPI/DR//SHABANA /UBIN/asgark/P aym AT | C33: 1000 | E33: 5633.47 | F33: =TEXT(Account_Data[[#This Row],[Date]],"mmm-yyyy") -> Apr-2025 | G33: =IF(Account_Data[[#This Row],[Credit]]>0,"Income","Expense") -> Expense | H33: =IF(AND(Account_Data[[#This Row],[Credit]]>0,ISNUMBER(SEARCH("TFR",Account_Data[[#This Row],[Details]])),Account_Data[[#This Row],[Credit]]>=200000),"Loan Taken", IF(AND(Account_Data[[#This Row],[Debit]]>0,OR(ISNUMBER(SEARCH("ETMONEY",Account_Data[[#This Row],[Details]])),ISNUMBER(SEARCH("PGIM",Account_Data[[#This Row],[Details]])),ISNUMBER(SEARCH("CANARA",Account_Data[[#This Row],[Details]])))),"Investment (Outflow)", IF(AND(Account_Data[[#This Row],[Credit]]>0,OR(ISNUMBER(SEARCH("PGIM",Account_Data[[#This Row],[Details]])),ISNUMBER(SEARCH("CANARA",Account_Data[[#This Row],[Details]])),ISNUMBER(SEARCH("MUTUAL",Account_Data[[#This Row],[Details]])))),"Investment Return", IF(OR(ISNUMBER(SEARCH("LOAN",Account_Data[[#This Row],[Details]])),ISNUMBER(SEARCH("RECOVERY",Account_Data[[#This Row],[Details]]))),"Loan Payment", IF(OR(ISNUMBER(SEARCH("SALARY",Account_Data[[#This Row],[Details]])),ISNUMBER(SEARCH("EMPLOYER DEP",Account_Data[[#This Row],[Details]]))),"Income", IF(OR(ISNUMBER(SEARCH("ACH",Account_Data[[#This Row],[Details]])),ISNUMBER(SEARCH("DIRECT DR",Account_Data[[#This Row],[Details]]))),"EMI", IF(ISNUMBER(SEARCH("ATM",Account_Data[[#This Row],[Details]])),"Cash", IF(ISNUMBER(SEARCH("UPI",Account_Data[[#This Row],[Details]])),"UPI Expense",IF(ISNUMBER(SEARCH("W TFR",Account_Data[[#This Row],[Details]])),"Transfer","Other"))))))))) -> UPI Expense | I33: =Account_Data[[#This Row],[Credit]]-Account_Data[[#This Row],[Debit]] -> -1000 | J33: =EOMONTH(Account_Data[[#This Row],[Date]],0) -> 45777 | K33: =ABS(Account_Data[[#This Row],[Amount]]) -> 1000
